<mujoco model="swimmer">
  <compiler angle="degree" coordinate="local" inertiafromgeom="true"/>
  <option density="4000" integrator="RK4" timestep="0.01" /> <!-- collision="predefined" viscosity="0.1"-->
  <default>
    <geom conaffinity="1" condim="3" contype="1" material="geom" density="5.0" friction="1 0.5 0.5" rgba="0.8 0.6 .4 1"/>
    <joint armature='1' damping="1"  />
  </default>
  <asset>
    <texture builtin="gradient" height="100" rgb1="1 1 1" rgb2="0 0 0" type="skybox" width="100"/>
    <texture builtin="flat" height="1278" mark="cross" markrgb="1 1 1" name="texgeom" random="0" rgb1="0.8 0.6 0.4" rgb2="0.8 0.6 0.4" type="cube" width="127"/>
    <texture builtin="checker" height="100" name="texplane" rgb1="0 0 0" rgb2="0.8 0.8 0.8" type="2d" width="100"/>
    <material name="MatPlane" reflectance="0.5" shininess="1" specular="1" texrepeat="30 30" texture="texplane"/>
    <material name="geom" texture="texgeom" texuniform="true"/>
  </asset>
  <worldbody>
    <light cutoff="100" diffuse="1 1 1" dir="-0 0 -1.3" directional="true" exponent="1" pos="0 0 1.3" specular=".1 .1 .1"/>
    <geom conaffinity="1" condim="3" material="MatPlane" name="floor" pos="0 0 -0.1" rgba="0.8 0.9 0.8 1" size="40 40 0.1" type="plane"/>
    
    <!--  ================= SWIMMER ================= /-->
    <body name="torso" pos="0 0 1">
      <geom density="1000" fromto="0 0 0 0.3 0 0" size="0.05" type="capsule"/>
      <!--<joint axis="1 0 0" name="slider1" pos="0 0 0" type="slide"/>
      <joint axis="0 1 0" name="slider2" pos="0 0 0" type="slide"/>
      <joint axis="0 0 1" name="rot" pos="0 0 0" type="hinge"/> -->
      <joint armature="1" damping="0" limited="false" margin="0.01" name="root-handicap__11" pos="0 0 0" type="free"/>
      <body name="mid" pos="0 0 0">
        <geom density="1000" fromto="0 0 0 -0.3 0 0" size="0.05" type="capsule"/>
        <joint axis="0 0 1" limited="true" name="rot2" pos="0 0 0" range="-100 100" type="hinge"/>
        <body name="back" pos="-0.3 0 0">
          <geom density="1000" fromto="0 0 0 -0.3 0 0" size="0.05" type="capsule"/>
          <joint axis="0 0 1" limited="true" name="rot3" pos="0 0 0" range="-100 100" type="hinge"/>
        </body>
      </body>
    </body>
     <!---
    <body  name="handicap" pos="0 0 0">
        <geom density="1000" name="kochka-4" pos="-2 0.5 0" size="0.05" type="sphere"/>
        <geom density="1000" name="kochka-3" pos="-1.5 0.5 0" size="0.05" type="sphere"/>
        <geom density="1000" name="kochka-2" pos="-1 0.5 0" size="0.05" type="sphere"/>
        <geom density="1000" name="kochka-1" pos="-0.5 0.5 0" size="0.05" type="sphere"/>
        <geom density="1000" name="kochka1" pos="0 0.5 0" size="0.05" type="sphere"/>
        <geom density="1000" name="kochka2" pos="0.5 0.5 0" size="0.05" type="sphere"/>
        <geom density="1000" name="kochka3" pos="1 0.5 0" size="0.05" type="sphere"/>
        <geom density="1000" name="kochka4" pos="1.5 0.5 0" size="0.05" type="sphere"/>
        <geom density="1000" name="kochka5" pos="2 0.5 0" size="0.05" type="sphere"/>
        
        <geom density="1000" name="2kochka-4" pos="-2 -0.5 0" size="0.05" type="sphere"/>
        <geom density="1000" name="2kochka-3" pos="-1.5 -0.5 0" size="0.05" type="sphere"/>
        <geom density="1000" name="2kochka-2" pos="-1 -0.5 0" size="0.05" type="sphere"/>
        <geom density="1000" name="2kochka-1" pos="-0.5 -0.5 0" size="0.05" type="sphere"/>
        <geom density="1000" name="2kochka1" pos="0 -0.5 0" size="0.05" type="sphere"/>
        <geom density="1000" name="2kochka2" pos="0.5 -0.5 0" size="0.05" type="sphere"/>
        <geom density="1000" name="2kochka3" pos="1 -0.5 0" size="0.05" type="sphere"/>
        <geom density="1000" name="2kochka4" pos="1.5 -0.5 0" size="0.05" type="sphere"/>
        <geom density="1000" name="2kochka5" pos="2 -0.5 0" size="0.05" type="sphere"/>
    </body> /-->
   
    <!--  ================= SWIMMER ================= /-->
    <body name="torso_sw2" pos="-2 0 1">
      <geom density="1000" fromto="0 0 0 0.3 0 0" size="0.05" type="capsule"/>
      <!--<joint axis="1 0 0" name="slider1" pos="0 0 0" type="slide"/>
      <joint axis="0 1 0" name="slider2" pos="0 0 0" type="slide"/>
      <joint axis="0 0 1" name="rot" pos="0 0 0" type="hinge"/> -->
      <joint armature="1" damping="0" limited="false" margin="0.01" name="root-handicap__11_sw2" pos="0 0 0" type="free"/>
      <body name="mid_sw2" pos="0 0 0">
        <geom density="1000" fromto="0 0 0 -0.3 0 0" size="0.05" type="capsule"/>
        <joint axis="0 0 1" limited="true" name="rot2_sw2" pos="0 0 0" range="-100 100" type="hinge"/>
        <body name="back_sw2" pos="-0.3 0 0">
          <geom density="1000" fromto="0 0 0 -0.3 0 0" size="0.05" type="capsule"/>
          <joint axis="0 0 1" limited="true" name="rot3_sw2" pos="0 0 0" range="-100 100" type="hinge"/>
        </body>
      </body>
    </body>

  </worldbody>
  <actuator>
    <motor ctrllimited="true" ctrlrange="-1 1" gear="150.0" joint="rot2"/>
    <motor ctrllimited="true" ctrlrange="-1 1" gear="150.0" joint="rot3"/>
    <motor ctrllimited="true" ctrlrange="-1 1" gear="150.0" joint="rot2_sw2"/>
    <motor ctrllimited="true" ctrlrange="-1 1" gear="150.0" joint="rot3_sw2"/>
  </actuator>
</mujoco>
